[2024-11-05T01:51:47.890+0000] {local_task_job_runner.py:123} INFO - ::group::Pre task execution logs
[2024-11-05T01:51:48.094+0000] {taskinstance.py:2612} INFO - Dependencies all met for dep_context=non-requeueable deps ti=<TaskInstance: model_training_update.train_model manual__2024-11-05T01:46:33.773994+00:00 [queued]>
[2024-11-05T01:51:48.125+0000] {taskinstance.py:2612} INFO - Dependencies all met for dep_context=requeueable deps ti=<TaskInstance: model_training_update.train_model manual__2024-11-05T01:46:33.773994+00:00 [queued]>
[2024-11-05T01:51:48.126+0000] {taskinstance.py:2865} INFO - Starting attempt 2 of 2
[2024-11-05T01:51:48.254+0000] {taskinstance.py:2888} INFO - Executing <Task(HttpOperator): train_model> on 2024-11-05 01:46:33.773994+00:00
[2024-11-05T01:51:48.285+0000] {logging_mixin.py:190} WARNING - /home/***/.local/lib/python3.12/site-packages/***/task/task_runner/standard_task_runner.py:70 DeprecationWarning: This process (pid=236) is multi-threaded, use of fork() may lead to deadlocks in the child.
[2024-11-05T01:51:48.301+0000] {standard_task_runner.py:72} INFO - Started process 237 to run task
[2024-11-05T01:51:48.291+0000] {standard_task_runner.py:104} INFO - Running: ['***', 'tasks', 'run', 'model_training_update', 'train_model', 'manual__2024-11-05T01:46:33.773994+00:00', '--job-id', '5', '--raw', '--subdir', 'DAGS_FOLDER/DAG.py', '--cfg-path', '/tmp/tmpzovgisc0']
[2024-11-05T01:51:48.309+0000] {standard_task_runner.py:105} INFO - Job 5: Subtask train_model
[2024-11-05T01:51:48.812+0000] {logging_mixin.py:190} WARNING - /home/***/.local/lib/python3.12/site-packages/***/settings.py:209 DeprecationWarning: The sql_alchemy_conn option in [core] has been moved to the sql_alchemy_conn option in [database] - the old setting has been used, but please update your config.
[2024-11-05T01:51:49.071+0000] {task_command.py:467} INFO - Running <TaskInstance: model_training_update.train_model manual__2024-11-05T01:46:33.773994+00:00 [running]> on host 99e6a43400bc
[2024-11-05T01:51:49.605+0000] {taskinstance.py:3131} INFO - Exporting env vars: AIRFLOW_CTX_DAG_OWNER='***' AIRFLOW_CTX_DAG_ID='model_training_update' AIRFLOW_CTX_TASK_ID='train_model' AIRFLOW_CTX_EXECUTION_DATE='2024-11-05T01:46:33.773994+00:00' AIRFLOW_CTX_TRY_NUMBER='2' AIRFLOW_CTX_DAG_RUN_ID='manual__2024-11-05T01:46:33.773994+00:00'
[2024-11-05T01:51:49.610+0000] {taskinstance.py:731} INFO - ::endgroup::
[2024-11-05T01:51:49.726+0000] {http.py:173} INFO - Calling HTTP method
[2024-11-05T01:51:49.794+0000] {base.py:84} INFO - Retrieving connection 'http://localhost:80/docs'
[2024-11-05T01:51:49.899+0000] {base.py:84} INFO - Retrieving connection 'http://localhost:80/docs'
[2024-11-05T01:51:49.930+0000] {taskinstance.py:3310} ERROR - Task failed with exception
Traceback (most recent call last):
  File "/home/airflow/.local/lib/python3.12/site-packages/airflow/models/taskinstance.py", line 767, in _execute_task
    result = _execute_callable(context=context, **execute_callable_kwargs)
             ^^^^^^^^^^^^^^^^^^^^^^^^^^^^^^^^^^^^^^^^^^^^^^^^^^^^^^^^^^^^^
  File "/home/airflow/.local/lib/python3.12/site-packages/airflow/models/taskinstance.py", line 733, in _execute_callable
    return ExecutionCallableRunner(
           ^^^^^^^^^^^^^^^^^^^^^^^^
  File "/home/airflow/.local/lib/python3.12/site-packages/airflow/utils/operator_helpers.py", line 252, in run
    return self.func(*args, **kwargs)
           ^^^^^^^^^^^^^^^^^^^^^^^^^^
  File "/home/airflow/.local/lib/python3.12/site-packages/airflow/models/baseoperator.py", line 406, in wrapper
    return func(self, *args, **kwargs)
           ^^^^^^^^^^^^^^^^^^^^^^^^^^^
  File "/home/airflow/.local/lib/python3.12/site-packages/airflow/providers/http/operators/http.py", line 170, in execute
    return self.execute_sync(context=context)
           ^^^^^^^^^^^^^^^^^^^^^^^^^^^^^^^^^^
  File "/home/airflow/.local/lib/python3.12/site-packages/airflow/providers/http/operators/http.py", line 179, in execute_sync
    response = self.hook.run(self.endpoint, self.data, self.headers, self.extra_options)
               ^^^^^^^^^^^^^^^^^^^^^^^^^^^^^^^^^^^^^^^^^^^^^^^^^^^^^^^^^^^^^^^^^^^^^^^^^
  File "/home/airflow/.local/lib/python3.12/site-packages/airflow/providers/http/hooks/http.py", line 189, in run
    prepped_request = session.prepare_request(req)
                      ^^^^^^^^^^^^^^^^^^^^^^^^^^^^
  File "/home/airflow/.local/lib/python3.12/site-packages/requests/sessions.py", line 484, in prepare_request
    p.prepare(
  File "/home/airflow/.local/lib/python3.12/site-packages/requests/models.py", line 367, in prepare
    self.prepare_url(url, params)
  File "/home/airflow/.local/lib/python3.12/site-packages/requests/models.py", line 444, in prepare_url
    raise InvalidURL(f"Invalid URL {url!r}: No host supplied")
requests.exceptions.InvalidURL: Invalid URL 'http:///train': No host supplied
[2024-11-05T01:51:50.049+0000] {taskinstance.py:1225} INFO - Marking task as FAILED. dag_id=model_training_update, task_id=train_model, run_id=manual__2024-11-05T01:46:33.773994+00:00, execution_date=20241105T014633, start_date=20241105T015148, end_date=20241105T015150
[2024-11-05T01:51:50.116+0000] {taskinstance.py:340} INFO - ::group::Post task execution logs
[2024-11-05T01:51:50.118+0000] {standard_task_runner.py:124} ERROR - Failed to execute job 5 for task train_model (Invalid URL 'http:///train': No host supplied; 237)
Traceback (most recent call last):
  File "/home/airflow/.local/lib/python3.12/site-packages/airflow/task/task_runner/standard_task_runner.py", line 117, in _start_by_fork
    ret = args.func(args, dag=self.dag)
          ^^^^^^^^^^^^^^^^^^^^^^^^^^^^^
  File "/home/airflow/.local/lib/python3.12/site-packages/airflow/cli/cli_config.py", line 49, in command
    return func(*args, **kwargs)
           ^^^^^^^^^^^^^^^^^^^^^
  File "/home/airflow/.local/lib/python3.12/site-packages/airflow/utils/cli.py", line 115, in wrapper
    return f(*args, **kwargs)
           ^^^^^^^^^^^^^^^^^^
  File "/home/airflow/.local/lib/python3.12/site-packages/airflow/cli/commands/task_command.py", line 483, in task_run
    task_return_code = _run_task_by_selected_method(args, _dag, ti)
                       ^^^^^^^^^^^^^^^^^^^^^^^^^^^^^^^^^^^^^^^^^^^^
  File "/home/airflow/.local/lib/python3.12/site-packages/airflow/cli/commands/task_command.py", line 256, in _run_task_by_selected_method
    return _run_raw_task(args, ti)
           ^^^^^^^^^^^^^^^^^^^^^^^
  File "/home/airflow/.local/lib/python3.12/site-packages/airflow/cli/commands/task_command.py", line 341, in _run_raw_task
    return ti._run_raw_task(
           ^^^^^^^^^^^^^^^^^
  File "/home/airflow/.local/lib/python3.12/site-packages/airflow/utils/session.py", line 97, in wrapper
    return func(*args, session=session, **kwargs)
           ^^^^^^^^^^^^^^^^^^^^^^^^^^^^^^^^^^^^^^
  File "/home/airflow/.local/lib/python3.12/site-packages/airflow/models/taskinstance.py", line 3004, in _run_raw_task
    return _run_raw_task(
           ^^^^^^^^^^^^^^
  File "/home/airflow/.local/lib/python3.12/site-packages/airflow/models/taskinstance.py", line 273, in _run_raw_task
    TaskInstance._execute_task_with_callbacks(
  File "/home/airflow/.local/lib/python3.12/site-packages/airflow/models/taskinstance.py", line 3158, in _execute_task_with_callbacks
    result = self._execute_task(context, task_orig)
             ^^^^^^^^^^^^^^^^^^^^^^^^^^^^^^^^^^^^^^
  File "/home/airflow/.local/lib/python3.12/site-packages/airflow/models/taskinstance.py", line 3182, in _execute_task
    return _execute_task(self, context, task_orig)
           ^^^^^^^^^^^^^^^^^^^^^^^^^^^^^^^^^^^^^^^
  File "/home/airflow/.local/lib/python3.12/site-packages/airflow/models/taskinstance.py", line 767, in _execute_task
    result = _execute_callable(context=context, **execute_callable_kwargs)
             ^^^^^^^^^^^^^^^^^^^^^^^^^^^^^^^^^^^^^^^^^^^^^^^^^^^^^^^^^^^^^
  File "/home/airflow/.local/lib/python3.12/site-packages/airflow/models/taskinstance.py", line 733, in _execute_callable
    return ExecutionCallableRunner(
           ^^^^^^^^^^^^^^^^^^^^^^^^
  File "/home/airflow/.local/lib/python3.12/site-packages/airflow/utils/operator_helpers.py", line 252, in run
    return self.func(*args, **kwargs)
           ^^^^^^^^^^^^^^^^^^^^^^^^^^
  File "/home/airflow/.local/lib/python3.12/site-packages/airflow/models/baseoperator.py", line 406, in wrapper
    return func(self, *args, **kwargs)
           ^^^^^^^^^^^^^^^^^^^^^^^^^^^
  File "/home/airflow/.local/lib/python3.12/site-packages/airflow/providers/http/operators/http.py", line 170, in execute
    return self.execute_sync(context=context)
           ^^^^^^^^^^^^^^^^^^^^^^^^^^^^^^^^^^
  File "/home/airflow/.local/lib/python3.12/site-packages/airflow/providers/http/operators/http.py", line 179, in execute_sync
    response = self.hook.run(self.endpoint, self.data, self.headers, self.extra_options)
               ^^^^^^^^^^^^^^^^^^^^^^^^^^^^^^^^^^^^^^^^^^^^^^^^^^^^^^^^^^^^^^^^^^^^^^^^^
  File "/home/airflow/.local/lib/python3.12/site-packages/airflow/providers/http/hooks/http.py", line 189, in run
    prepped_request = session.prepare_request(req)
                      ^^^^^^^^^^^^^^^^^^^^^^^^^^^^
  File "/home/airflow/.local/lib/python3.12/site-packages/requests/sessions.py", line 484, in prepare_request
    p.prepare(
  File "/home/airflow/.local/lib/python3.12/site-packages/requests/models.py", line 367, in prepare
    self.prepare_url(url, params)
  File "/home/airflow/.local/lib/python3.12/site-packages/requests/models.py", line 444, in prepare_url
    raise InvalidURL(f"Invalid URL {url!r}: No host supplied")
requests.exceptions.InvalidURL: Invalid URL 'http:///train': No host supplied
[2024-11-05T01:51:50.167+0000] {local_task_job_runner.py:266} INFO - Task exited with return code 1
[2024-11-05T01:51:50.229+0000] {local_task_job_runner.py:245} INFO - ::endgroup::
