[2024-11-14T00:02:02.830+0000] {local_task_job_runner.py:123} INFO - ::group::Pre task execution logs
[2024-11-14T00:02:02.887+0000] {taskinstance.py:2612} INFO - Dependencies all met for dep_context=non-requeueable deps ti=<TaskInstance: model_training_update.train_model scheduled__2024-11-13T00:00:00+00:00 [queued]>
[2024-11-14T00:02:02.902+0000] {taskinstance.py:2612} INFO - Dependencies all met for dep_context=requeueable deps ti=<TaskInstance: model_training_update.train_model scheduled__2024-11-13T00:00:00+00:00 [queued]>
[2024-11-14T00:02:02.903+0000] {taskinstance.py:2865} INFO - Starting attempt 1 of 2
[2024-11-14T00:02:02.931+0000] {taskinstance.py:2888} INFO - Executing <Task(HttpOperator): train_model> on 2024-11-13 00:00:00+00:00
[2024-11-14T00:02:02.950+0000] {logging_mixin.py:190} WARNING - /home/***/.local/lib/python3.12/site-packages/***/task/task_runner/standard_task_runner.py:70 DeprecationWarning: This process (pid=169) is multi-threaded, use of fork() may lead to deadlocks in the child.
[2024-11-14T00:02:02.952+0000] {standard_task_runner.py:72} INFO - Started process 172 to run task
[2024-11-14T00:02:02.947+0000] {standard_task_runner.py:104} INFO - Running: ['***', 'tasks', 'run', 'model_training_update', 'train_model', 'scheduled__2024-11-13T00:00:00+00:00', '--job-id', '41', '--raw', '--subdir', 'DAGS_FOLDER/DAG.py', '--cfg-path', '/tmp/tmpxpso1469']
[2024-11-14T00:02:02.953+0000] {standard_task_runner.py:105} INFO - Job 41: Subtask train_model
[2024-11-14T00:02:03.019+0000] {logging_mixin.py:190} WARNING - /home/***/.local/lib/python3.12/site-packages/***/settings.py:209 DeprecationWarning: The sql_alchemy_conn option in [core] has been moved to the sql_alchemy_conn option in [database] - the old setting has been used, but please update your config.
[2024-11-14T00:02:03.174+0000] {task_command.py:467} INFO - Running <TaskInstance: model_training_update.train_model scheduled__2024-11-13T00:00:00+00:00 [running]> on host 3a1a142eac70
[2024-11-14T00:02:03.179+0000] {logging_mixin.py:190} WARNING - /home/***/.local/lib/python3.12/site-packages/***/settings.py:470 DeprecationWarning: The sql_alchemy_conn option in [core] has been moved to the sql_alchemy_conn option in [database] - the old setting has been used, but please update your config.
[2024-11-14T00:02:03.589+0000] {taskinstance.py:3131} INFO - Exporting env vars: AIRFLOW_CTX_DAG_OWNER='***' AIRFLOW_CTX_DAG_ID='model_training_update' AIRFLOW_CTX_TASK_ID='train_model' AIRFLOW_CTX_EXECUTION_DATE='2024-11-13T00:00:00+00:00' AIRFLOW_CTX_TRY_NUMBER='1' AIRFLOW_CTX_DAG_RUN_ID='scheduled__2024-11-13T00:00:00+00:00'
[2024-11-14T00:02:03.591+0000] {taskinstance.py:731} INFO - ::endgroup::
[2024-11-14T00:02:03.707+0000] {http.py:173} INFO - Calling HTTP method
[2024-11-14T00:02:03.764+0000] {base.py:84} INFO - Retrieving connection 'ventes'
[2024-11-14T00:02:03.833+0000] {base.py:84} INFO - Retrieving connection 'ventes'
[2024-11-14T00:02:03.853+0000] {http.py:248} WARNING - HTTPConnectionPool(host='localhost', port=80): Max retries exceeded with url: /docs/train (Caused by NewConnectionError('<urllib3.connection.HTTPConnection object at 0x7febe2930680>: Failed to establish a new connection: [Errno 111] Connection refused')) Tenacity will retry to execute the operation
[2024-11-14T00:02:03.856+0000] {taskinstance.py:3310} ERROR - Task failed with exception
Traceback (most recent call last):
  File "/home/airflow/.local/lib/python3.12/site-packages/urllib3/connection.py", line 196, in _new_conn
    sock = connection.create_connection(
           ^^^^^^^^^^^^^^^^^^^^^^^^^^^^^
  File "/home/airflow/.local/lib/python3.12/site-packages/urllib3/util/connection.py", line 85, in create_connection
    raise err
  File "/home/airflow/.local/lib/python3.12/site-packages/urllib3/util/connection.py", line 73, in create_connection
    sock.connect(sa)
ConnectionRefusedError: [Errno 111] Connection refused

The above exception was the direct cause of the following exception:

Traceback (most recent call last):
  File "/home/airflow/.local/lib/python3.12/site-packages/urllib3/connectionpool.py", line 789, in urlopen
    response = self._make_request(
               ^^^^^^^^^^^^^^^^^^^
  File "/home/airflow/.local/lib/python3.12/site-packages/urllib3/connectionpool.py", line 495, in _make_request
    conn.request(
  File "/home/airflow/.local/lib/python3.12/site-packages/urllib3/connection.py", line 398, in request
    self.endheaders()
  File "/usr/local/lib/python3.12/http/client.py", line 1331, in endheaders
    self._send_output(message_body, encode_chunked=encode_chunked)
  File "/usr/local/lib/python3.12/http/client.py", line 1091, in _send_output
    self.send(msg)
  File "/usr/local/lib/python3.12/http/client.py", line 1035, in send
    self.connect()
  File "/home/airflow/.local/lib/python3.12/site-packages/urllib3/connection.py", line 236, in connect
    self.sock = self._new_conn()
                ^^^^^^^^^^^^^^^^
  File "/home/airflow/.local/lib/python3.12/site-packages/urllib3/connection.py", line 211, in _new_conn
    raise NewConnectionError(
urllib3.exceptions.NewConnectionError: <urllib3.connection.HTTPConnection object at 0x7febe2930680>: Failed to establish a new connection: [Errno 111] Connection refused

The above exception was the direct cause of the following exception:

Traceback (most recent call last):
  File "/home/airflow/.local/lib/python3.12/site-packages/requests/adapters.py", line 667, in send
    resp = conn.urlopen(
           ^^^^^^^^^^^^^
  File "/home/airflow/.local/lib/python3.12/site-packages/urllib3/connectionpool.py", line 843, in urlopen
    retries = retries.increment(
              ^^^^^^^^^^^^^^^^^^
  File "/home/airflow/.local/lib/python3.12/site-packages/urllib3/util/retry.py", line 519, in increment
    raise MaxRetryError(_pool, url, reason) from reason  # type: ignore[arg-type]
    ^^^^^^^^^^^^^^^^^^^^^^^^^^^^^^^^^^^^^^^^^^^^^^^^^^^
urllib3.exceptions.MaxRetryError: HTTPConnectionPool(host='localhost', port=80): Max retries exceeded with url: /docs/train (Caused by NewConnectionError('<urllib3.connection.HTTPConnection object at 0x7febe2930680>: Failed to establish a new connection: [Errno 111] Connection refused'))

During handling of the above exception, another exception occurred:

Traceback (most recent call last):
  File "/home/airflow/.local/lib/python3.12/site-packages/airflow/models/taskinstance.py", line 767, in _execute_task
    result = _execute_callable(context=context, **execute_callable_kwargs)
             ^^^^^^^^^^^^^^^^^^^^^^^^^^^^^^^^^^^^^^^^^^^^^^^^^^^^^^^^^^^^^
  File "/home/airflow/.local/lib/python3.12/site-packages/airflow/models/taskinstance.py", line 733, in _execute_callable
    return ExecutionCallableRunner(
           ^^^^^^^^^^^^^^^^^^^^^^^^
  File "/home/airflow/.local/lib/python3.12/site-packages/airflow/utils/operator_helpers.py", line 252, in run
    return self.func(*args, **kwargs)
           ^^^^^^^^^^^^^^^^^^^^^^^^^^
  File "/home/airflow/.local/lib/python3.12/site-packages/airflow/models/baseoperator.py", line 406, in wrapper
    return func(self, *args, **kwargs)
           ^^^^^^^^^^^^^^^^^^^^^^^^^^^
  File "/home/airflow/.local/lib/python3.12/site-packages/airflow/providers/http/operators/http.py", line 170, in execute
    return self.execute_sync(context=context)
           ^^^^^^^^^^^^^^^^^^^^^^^^^^^^^^^^^^
  File "/home/airflow/.local/lib/python3.12/site-packages/airflow/providers/http/operators/http.py", line 179, in execute_sync
    response = self.hook.run(self.endpoint, self.data, self.headers, self.extra_options)
               ^^^^^^^^^^^^^^^^^^^^^^^^^^^^^^^^^^^^^^^^^^^^^^^^^^^^^^^^^^^^^^^^^^^^^^^^^
  File "/home/airflow/.local/lib/python3.12/site-packages/airflow/providers/http/hooks/http.py", line 191, in run
    return self.run_and_check(session, prepped_request, extra_options)
           ^^^^^^^^^^^^^^^^^^^^^^^^^^^^^^^^^^^^^^^^^^^^^^^^^^^^^^^^^^^
  File "/home/airflow/.local/lib/python3.12/site-packages/airflow/providers/http/hooks/http.py", line 249, in run_and_check
    raise ex
  File "/home/airflow/.local/lib/python3.12/site-packages/airflow/providers/http/hooks/http.py", line 241, in run_and_check
    response = session.send(prepped_request, **send_kwargs)
               ^^^^^^^^^^^^^^^^^^^^^^^^^^^^^^^^^^^^^^^^^^^^
  File "/home/airflow/.local/lib/python3.12/site-packages/requests/sessions.py", line 703, in send
    r = adapter.send(request, **kwargs)
        ^^^^^^^^^^^^^^^^^^^^^^^^^^^^^^^
  File "/home/airflow/.local/lib/python3.12/site-packages/requests/adapters.py", line 700, in send
    raise ConnectionError(e, request=request)
requests.exceptions.ConnectionError: HTTPConnectionPool(host='localhost', port=80): Max retries exceeded with url: /docs/train (Caused by NewConnectionError('<urllib3.connection.HTTPConnection object at 0x7febe2930680>: Failed to establish a new connection: [Errno 111] Connection refused'))
[2024-11-14T00:02:04.094+0000] {taskinstance.py:1225} INFO - Marking task as UP_FOR_RETRY. dag_id=model_training_update, task_id=train_model, run_id=scheduled__2024-11-13T00:00:00+00:00, execution_date=20241113T000000, start_date=20241114T000202, end_date=20241114T000204
[2024-11-14T00:02:04.176+0000] {taskinstance.py:340} INFO - ::group::Post task execution logs
[2024-11-14T00:02:04.178+0000] {standard_task_runner.py:124} ERROR - Failed to execute job 41 for task train_model (HTTPConnectionPool(host='localhost', port=80): Max retries exceeded with url: /docs/train (Caused by NewConnectionError('<urllib3.connection.HTTPConnection object at 0x7febe2930680>: Failed to establish a new connection: [Errno 111] Connection refused')); 172)
Traceback (most recent call last):
  File "/home/airflow/.local/lib/python3.12/site-packages/urllib3/connection.py", line 196, in _new_conn
    sock = connection.create_connection(
           ^^^^^^^^^^^^^^^^^^^^^^^^^^^^^
  File "/home/airflow/.local/lib/python3.12/site-packages/urllib3/util/connection.py", line 85, in create_connection
    raise err
  File "/home/airflow/.local/lib/python3.12/site-packages/urllib3/util/connection.py", line 73, in create_connection
    sock.connect(sa)
ConnectionRefusedError: [Errno 111] Connection refused

The above exception was the direct cause of the following exception:

Traceback (most recent call last):
  File "/home/airflow/.local/lib/python3.12/site-packages/urllib3/connectionpool.py", line 789, in urlopen
    response = self._make_request(
               ^^^^^^^^^^^^^^^^^^^
  File "/home/airflow/.local/lib/python3.12/site-packages/urllib3/connectionpool.py", line 495, in _make_request
    conn.request(
  File "/home/airflow/.local/lib/python3.12/site-packages/urllib3/connection.py", line 398, in request
    self.endheaders()
  File "/usr/local/lib/python3.12/http/client.py", line 1331, in endheaders
    self._send_output(message_body, encode_chunked=encode_chunked)
  File "/usr/local/lib/python3.12/http/client.py", line 1091, in _send_output
    self.send(msg)
  File "/usr/local/lib/python3.12/http/client.py", line 1035, in send
    self.connect()
  File "/home/airflow/.local/lib/python3.12/site-packages/urllib3/connection.py", line 236, in connect
    self.sock = self._new_conn()
                ^^^^^^^^^^^^^^^^
  File "/home/airflow/.local/lib/python3.12/site-packages/urllib3/connection.py", line 211, in _new_conn
    raise NewConnectionError(
urllib3.exceptions.NewConnectionError: <urllib3.connection.HTTPConnection object at 0x7febe2930680>: Failed to establish a new connection: [Errno 111] Connection refused

The above exception was the direct cause of the following exception:

Traceback (most recent call last):
  File "/home/airflow/.local/lib/python3.12/site-packages/requests/adapters.py", line 667, in send
    resp = conn.urlopen(
           ^^^^^^^^^^^^^
  File "/home/airflow/.local/lib/python3.12/site-packages/urllib3/connectionpool.py", line 843, in urlopen
    retries = retries.increment(
              ^^^^^^^^^^^^^^^^^^
  File "/home/airflow/.local/lib/python3.12/site-packages/urllib3/util/retry.py", line 519, in increment
    raise MaxRetryError(_pool, url, reason) from reason  # type: ignore[arg-type]
    ^^^^^^^^^^^^^^^^^^^^^^^^^^^^^^^^^^^^^^^^^^^^^^^^^^^
urllib3.exceptions.MaxRetryError: HTTPConnectionPool(host='localhost', port=80): Max retries exceeded with url: /docs/train (Caused by NewConnectionError('<urllib3.connection.HTTPConnection object at 0x7febe2930680>: Failed to establish a new connection: [Errno 111] Connection refused'))

During handling of the above exception, another exception occurred:

Traceback (most recent call last):
  File "/home/airflow/.local/lib/python3.12/site-packages/airflow/task/task_runner/standard_task_runner.py", line 117, in _start_by_fork
    ret = args.func(args, dag=self.dag)
          ^^^^^^^^^^^^^^^^^^^^^^^^^^^^^
  File "/home/airflow/.local/lib/python3.12/site-packages/airflow/cli/cli_config.py", line 49, in command
    return func(*args, **kwargs)
           ^^^^^^^^^^^^^^^^^^^^^
  File "/home/airflow/.local/lib/python3.12/site-packages/airflow/utils/cli.py", line 115, in wrapper
    return f(*args, **kwargs)
           ^^^^^^^^^^^^^^^^^^
  File "/home/airflow/.local/lib/python3.12/site-packages/airflow/cli/commands/task_command.py", line 483, in task_run
    task_return_code = _run_task_by_selected_method(args, _dag, ti)
                       ^^^^^^^^^^^^^^^^^^^^^^^^^^^^^^^^^^^^^^^^^^^^
  File "/home/airflow/.local/lib/python3.12/site-packages/airflow/cli/commands/task_command.py", line 256, in _run_task_by_selected_method
    return _run_raw_task(args, ti)
           ^^^^^^^^^^^^^^^^^^^^^^^
  File "/home/airflow/.local/lib/python3.12/site-packages/airflow/cli/commands/task_command.py", line 341, in _run_raw_task
    return ti._run_raw_task(
           ^^^^^^^^^^^^^^^^^
  File "/home/airflow/.local/lib/python3.12/site-packages/airflow/utils/session.py", line 97, in wrapper
    return func(*args, session=session, **kwargs)
           ^^^^^^^^^^^^^^^^^^^^^^^^^^^^^^^^^^^^^^
  File "/home/airflow/.local/lib/python3.12/site-packages/airflow/models/taskinstance.py", line 3004, in _run_raw_task
    return _run_raw_task(
           ^^^^^^^^^^^^^^
  File "/home/airflow/.local/lib/python3.12/site-packages/airflow/models/taskinstance.py", line 273, in _run_raw_task
    TaskInstance._execute_task_with_callbacks(
  File "/home/airflow/.local/lib/python3.12/site-packages/airflow/models/taskinstance.py", line 3158, in _execute_task_with_callbacks
    result = self._execute_task(context, task_orig)
             ^^^^^^^^^^^^^^^^^^^^^^^^^^^^^^^^^^^^^^
  File "/home/airflow/.local/lib/python3.12/site-packages/airflow/models/taskinstance.py", line 3182, in _execute_task
    return _execute_task(self, context, task_orig)
           ^^^^^^^^^^^^^^^^^^^^^^^^^^^^^^^^^^^^^^^
  File "/home/airflow/.local/lib/python3.12/site-packages/airflow/models/taskinstance.py", line 767, in _execute_task
    result = _execute_callable(context=context, **execute_callable_kwargs)
             ^^^^^^^^^^^^^^^^^^^^^^^^^^^^^^^^^^^^^^^^^^^^^^^^^^^^^^^^^^^^^
  File "/home/airflow/.local/lib/python3.12/site-packages/airflow/models/taskinstance.py", line 733, in _execute_callable
    return ExecutionCallableRunner(
           ^^^^^^^^^^^^^^^^^^^^^^^^
  File "/home/airflow/.local/lib/python3.12/site-packages/airflow/utils/operator_helpers.py", line 252, in run
    return self.func(*args, **kwargs)
           ^^^^^^^^^^^^^^^^^^^^^^^^^^
  File "/home/airflow/.local/lib/python3.12/site-packages/airflow/models/baseoperator.py", line 406, in wrapper
    return func(self, *args, **kwargs)
           ^^^^^^^^^^^^^^^^^^^^^^^^^^^
  File "/home/airflow/.local/lib/python3.12/site-packages/airflow/providers/http/operators/http.py", line 170, in execute
    return self.execute_sync(context=context)
           ^^^^^^^^^^^^^^^^^^^^^^^^^^^^^^^^^^
  File "/home/airflow/.local/lib/python3.12/site-packages/airflow/providers/http/operators/http.py", line 179, in execute_sync
    response = self.hook.run(self.endpoint, self.data, self.headers, self.extra_options)
               ^^^^^^^^^^^^^^^^^^^^^^^^^^^^^^^^^^^^^^^^^^^^^^^^^^^^^^^^^^^^^^^^^^^^^^^^^
  File "/home/airflow/.local/lib/python3.12/site-packages/airflow/providers/http/hooks/http.py", line 191, in run
    return self.run_and_check(session, prepped_request, extra_options)
           ^^^^^^^^^^^^^^^^^^^^^^^^^^^^^^^^^^^^^^^^^^^^^^^^^^^^^^^^^^^
  File "/home/airflow/.local/lib/python3.12/site-packages/airflow/providers/http/hooks/http.py", line 249, in run_and_check
    raise ex
  File "/home/airflow/.local/lib/python3.12/site-packages/airflow/providers/http/hooks/http.py", line 241, in run_and_check
    response = session.send(prepped_request, **send_kwargs)
               ^^^^^^^^^^^^^^^^^^^^^^^^^^^^^^^^^^^^^^^^^^^^
  File "/home/airflow/.local/lib/python3.12/site-packages/requests/sessions.py", line 703, in send
    r = adapter.send(request, **kwargs)
        ^^^^^^^^^^^^^^^^^^^^^^^^^^^^^^^
  File "/home/airflow/.local/lib/python3.12/site-packages/requests/adapters.py", line 700, in send
    raise ConnectionError(e, request=request)
requests.exceptions.ConnectionError: HTTPConnectionPool(host='localhost', port=80): Max retries exceeded with url: /docs/train (Caused by NewConnectionError('<urllib3.connection.HTTPConnection object at 0x7febe2930680>: Failed to establish a new connection: [Errno 111] Connection refused'))
[2024-11-14T00:02:04.229+0000] {local_task_job_runner.py:266} INFO - Task exited with return code 1
[2024-11-14T00:02:04.321+0000] {taskinstance.py:3900} INFO - 0 downstream tasks scheduled from follow-on schedule check
[2024-11-14T00:02:04.325+0000] {local_task_job_runner.py:245} INFO - ::endgroup::
[2024-11-14T02:49:09.318+0000] {local_task_job_runner.py:123} INFO - ::group::Pre task execution logs
[2024-11-14T02:49:09.741+0000] {taskinstance.py:2612} INFO - Dependencies all met for dep_context=non-requeueable deps ti=<TaskInstance: model_training_update.train_model scheduled__2024-11-13T00:00:00+00:00 [queued]>
[2024-11-14T02:49:09.846+0000] {taskinstance.py:2612} INFO - Dependencies all met for dep_context=requeueable deps ti=<TaskInstance: model_training_update.train_model scheduled__2024-11-13T00:00:00+00:00 [queued]>
[2024-11-14T02:49:09.848+0000] {taskinstance.py:2865} INFO - Starting attempt 1 of 2
[2024-11-14T02:49:09.966+0000] {taskinstance.py:2888} INFO - Executing <Task(HttpOperator): train_model> on 2024-11-13 00:00:00+00:00
[2024-11-14T02:49:10.010+0000] {logging_mixin.py:190} WARNING - /home/***/.local/lib/python3.12/site-packages/***/task/task_runner/standard_task_runner.py:70 DeprecationWarning: This process (pid=230) is multi-threaded, use of fork() may lead to deadlocks in the child.
[2024-11-14T02:49:10.015+0000] {standard_task_runner.py:72} INFO - Started process 233 to run task
[2024-11-14T02:49:10.021+0000] {standard_task_runner.py:104} INFO - Running: ['***', 'tasks', 'run', 'model_training_update', 'train_model', 'scheduled__2024-11-13T00:00:00+00:00', '--job-id', '2', '--raw', '--subdir', 'DAGS_FOLDER/DAG.py', '--cfg-path', '/tmp/tmpyfpz8arg']
[2024-11-14T02:49:10.026+0000] {standard_task_runner.py:105} INFO - Job 2: Subtask train_model
[2024-11-14T02:49:10.320+0000] {logging_mixin.py:190} WARNING - /home/***/.local/lib/python3.12/site-packages/***/settings.py:209 DeprecationWarning: The sql_alchemy_conn option in [core] has been moved to the sql_alchemy_conn option in [database] - the old setting has been used, but please update your config.
[2024-11-14T02:49:11.170+0000] {task_command.py:467} INFO - Running <TaskInstance: model_training_update.train_model scheduled__2024-11-13T00:00:00+00:00 [running]> on host 5cee826b5bf3
[2024-11-14T02:49:11.201+0000] {logging_mixin.py:190} WARNING - /home/***/.local/lib/python3.12/site-packages/***/settings.py:470 DeprecationWarning: The sql_alchemy_conn option in [core] has been moved to the sql_alchemy_conn option in [database] - the old setting has been used, but please update your config.
[2024-11-14T02:49:12.326+0000] {taskinstance.py:3131} INFO - Exporting env vars: AIRFLOW_CTX_DAG_OWNER='***' AIRFLOW_CTX_DAG_ID='model_training_update' AIRFLOW_CTX_TASK_ID='train_model' AIRFLOW_CTX_EXECUTION_DATE='2024-11-13T00:00:00+00:00' AIRFLOW_CTX_TRY_NUMBER='1' AIRFLOW_CTX_DAG_RUN_ID='scheduled__2024-11-13T00:00:00+00:00'
[2024-11-14T02:49:12.331+0000] {taskinstance.py:731} INFO - ::endgroup::
[2024-11-14T02:49:12.567+0000] {http.py:173} INFO - Calling HTTP method
[2024-11-14T02:49:12.655+0000] {taskinstance.py:3310} ERROR - Task failed with exception
Traceback (most recent call last):
  File "/home/airflow/.local/lib/python3.12/site-packages/airflow/models/taskinstance.py", line 767, in _execute_task
    result = _execute_callable(context=context, **execute_callable_kwargs)
             ^^^^^^^^^^^^^^^^^^^^^^^^^^^^^^^^^^^^^^^^^^^^^^^^^^^^^^^^^^^^^
  File "/home/airflow/.local/lib/python3.12/site-packages/airflow/models/taskinstance.py", line 733, in _execute_callable
    return ExecutionCallableRunner(
           ^^^^^^^^^^^^^^^^^^^^^^^^
  File "/home/airflow/.local/lib/python3.12/site-packages/airflow/utils/operator_helpers.py", line 252, in run
    return self.func(*args, **kwargs)
           ^^^^^^^^^^^^^^^^^^^^^^^^^^
  File "/home/airflow/.local/lib/python3.12/site-packages/airflow/models/baseoperator.py", line 406, in wrapper
    return func(self, *args, **kwargs)
           ^^^^^^^^^^^^^^^^^^^^^^^^^^^
  File "/home/airflow/.local/lib/python3.12/site-packages/airflow/providers/http/operators/http.py", line 170, in execute
    return self.execute_sync(context=context)
           ^^^^^^^^^^^^^^^^^^^^^^^^^^^^^^^^^^
  File "/home/airflow/.local/lib/python3.12/site-packages/airflow/providers/http/operators/http.py", line 179, in execute_sync
    response = self.hook.run(self.endpoint, self.data, self.headers, self.extra_options)
               ^^^^^^^^^
  File "/home/airflow/.local/lib/python3.12/site-packages/airflow/providers/http/operators/http.py", line 152, in hook
    conn = BaseHook.get_connection(conn_id)
           ^^^^^^^^^^^^^^^^^^^^^^^^^^^^^^^^
  File "/home/airflow/.local/lib/python3.12/site-packages/airflow/hooks/base.py", line 83, in get_connection
    conn = Connection.get_connection_from_secrets(conn_id)
           ^^^^^^^^^^^^^^^^^^^^^^^^^^^^^^^^^^^^^^^^^^^^^^^
  File "/home/airflow/.local/lib/python3.12/site-packages/airflow/models/connection.py", line 537, in get_connection_from_secrets
    raise AirflowNotFoundException(f"The conn_id `{conn_id}` isn't defined")
airflow.exceptions.AirflowNotFoundException: The conn_id `fastapi` isn't defined
[2024-11-14T02:49:13.028+0000] {taskinstance.py:1225} INFO - Marking task as UP_FOR_RETRY. dag_id=model_training_update, task_id=train_model, run_id=scheduled__2024-11-13T00:00:00+00:00, execution_date=20241113T000000, start_date=20241114T024909, end_date=20241114T024913
[2024-11-14T02:49:13.332+0000] {taskinstance.py:340} INFO - ::group::Post task execution logs
[2024-11-14T02:49:13.340+0000] {standard_task_runner.py:124} ERROR - Failed to execute job 2 for task train_model (The conn_id `fastapi` isn't defined; 233)
Traceback (most recent call last):
  File "/home/airflow/.local/lib/python3.12/site-packages/airflow/task/task_runner/standard_task_runner.py", line 117, in _start_by_fork
    ret = args.func(args, dag=self.dag)
          ^^^^^^^^^^^^^^^^^^^^^^^^^^^^^
  File "/home/airflow/.local/lib/python3.12/site-packages/airflow/cli/cli_config.py", line 49, in command
    return func(*args, **kwargs)
           ^^^^^^^^^^^^^^^^^^^^^
  File "/home/airflow/.local/lib/python3.12/site-packages/airflow/utils/cli.py", line 115, in wrapper
    return f(*args, **kwargs)
           ^^^^^^^^^^^^^^^^^^
  File "/home/airflow/.local/lib/python3.12/site-packages/airflow/cli/commands/task_command.py", line 483, in task_run
    task_return_code = _run_task_by_selected_method(args, _dag, ti)
                       ^^^^^^^^^^^^^^^^^^^^^^^^^^^^^^^^^^^^^^^^^^^^
  File "/home/airflow/.local/lib/python3.12/site-packages/airflow/cli/commands/task_command.py", line 256, in _run_task_by_selected_method
    return _run_raw_task(args, ti)
           ^^^^^^^^^^^^^^^^^^^^^^^
  File "/home/airflow/.local/lib/python3.12/site-packages/airflow/cli/commands/task_command.py", line 341, in _run_raw_task
    return ti._run_raw_task(
           ^^^^^^^^^^^^^^^^^
  File "/home/airflow/.local/lib/python3.12/site-packages/airflow/utils/session.py", line 97, in wrapper
    return func(*args, session=session, **kwargs)
           ^^^^^^^^^^^^^^^^^^^^^^^^^^^^^^^^^^^^^^
  File "/home/airflow/.local/lib/python3.12/site-packages/airflow/models/taskinstance.py", line 3004, in _run_raw_task
    return _run_raw_task(
           ^^^^^^^^^^^^^^
  File "/home/airflow/.local/lib/python3.12/site-packages/airflow/models/taskinstance.py", line 273, in _run_raw_task
    TaskInstance._execute_task_with_callbacks(
  File "/home/airflow/.local/lib/python3.12/site-packages/airflow/models/taskinstance.py", line 3158, in _execute_task_with_callbacks
    result = self._execute_task(context, task_orig)
             ^^^^^^^^^^^^^^^^^^^^^^^^^^^^^^^^^^^^^^
  File "/home/airflow/.local/lib/python3.12/site-packages/airflow/models/taskinstance.py", line 3182, in _execute_task
    return _execute_task(self, context, task_orig)
           ^^^^^^^^^^^^^^^^^^^^^^^^^^^^^^^^^^^^^^^
  File "/home/airflow/.local/lib/python3.12/site-packages/airflow/models/taskinstance.py", line 767, in _execute_task
    result = _execute_callable(context=context, **execute_callable_kwargs)
             ^^^^^^^^^^^^^^^^^^^^^^^^^^^^^^^^^^^^^^^^^^^^^^^^^^^^^^^^^^^^^
  File "/home/airflow/.local/lib/python3.12/site-packages/airflow/models/taskinstance.py", line 733, in _execute_callable
    return ExecutionCallableRunner(
           ^^^^^^^^^^^^^^^^^^^^^^^^
  File "/home/airflow/.local/lib/python3.12/site-packages/airflow/utils/operator_helpers.py", line 252, in run
    return self.func(*args, **kwargs)
           ^^^^^^^^^^^^^^^^^^^^^^^^^^
  File "/home/airflow/.local/lib/python3.12/site-packages/airflow/models/baseoperator.py", line 406, in wrapper
    return func(self, *args, **kwargs)
           ^^^^^^^^^^^^^^^^^^^^^^^^^^^
  File "/home/airflow/.local/lib/python3.12/site-packages/airflow/providers/http/operators/http.py", line 170, in execute
    return self.execute_sync(context=context)
           ^^^^^^^^^^^^^^^^^^^^^^^^^^^^^^^^^^
  File "/home/airflow/.local/lib/python3.12/site-packages/airflow/providers/http/operators/http.py", line 179, in execute_sync
    response = self.hook.run(self.endpoint, self.data, self.headers, self.extra_options)
               ^^^^^^^^^
  File "/home/airflow/.local/lib/python3.12/site-packages/airflow/providers/http/operators/http.py", line 152, in hook
    conn = BaseHook.get_connection(conn_id)
           ^^^^^^^^^^^^^^^^^^^^^^^^^^^^^^^^
  File "/home/airflow/.local/lib/python3.12/site-packages/airflow/hooks/base.py", line 83, in get_connection
    conn = Connection.get_connection_from_secrets(conn_id)
           ^^^^^^^^^^^^^^^^^^^^^^^^^^^^^^^^^^^^^^^^^^^^^^^
  File "/home/airflow/.local/lib/python3.12/site-packages/airflow/models/connection.py", line 537, in get_connection_from_secrets
    raise AirflowNotFoundException(f"The conn_id `{conn_id}` isn't defined")
airflow.exceptions.AirflowNotFoundException: The conn_id `fastapi` isn't defined
[2024-11-14T02:49:13.440+0000] {local_task_job_runner.py:266} INFO - Task exited with return code 1
[2024-11-14T02:49:13.576+0000] {taskinstance.py:3900} INFO - 0 downstream tasks scheduled from follow-on schedule check
[2024-11-14T02:49:13.585+0000] {local_task_job_runner.py:245} INFO - ::endgroup::
[2024-11-14T03:22:13.176+0000] {local_task_job_runner.py:123} INFO - ::group::Pre task execution logs
[2024-11-14T03:22:13.253+0000] {taskinstance.py:2612} INFO - Dependencies all met for dep_context=non-requeueable deps ti=<TaskInstance: model_training_update.train_model scheduled__2024-11-13T00:00:00+00:00 [queued]>
[2024-11-14T03:22:13.312+0000] {taskinstance.py:2612} INFO - Dependencies all met for dep_context=requeueable deps ti=<TaskInstance: model_training_update.train_model scheduled__2024-11-13T00:00:00+00:00 [queued]>
[2024-11-14T03:22:13.314+0000] {taskinstance.py:2865} INFO - Starting attempt 1 of 2
[2024-11-14T03:22:13.492+0000] {taskinstance.py:2888} INFO - Executing <Task(HttpOperator): train_model> on 2024-11-13 00:00:00+00:00
[2024-11-14T03:22:13.538+0000] {standard_task_runner.py:104} INFO - Running: ['***', 'tasks', 'run', 'model_training_update', 'train_model', 'scheduled__2024-11-13T00:00:00+00:00', '--job-id', '2', '--raw', '--subdir', 'DAGS_FOLDER/DAG.py', '--cfg-path', '/tmp/tmpjsossyee']
[2024-11-14T03:22:13.545+0000] {standard_task_runner.py:105} INFO - Job 2: Subtask train_model
[2024-11-14T03:22:13.548+0000] {logging_mixin.py:190} WARNING - /home/***/.local/lib/python3.12/site-packages/***/task/task_runner/standard_task_runner.py:70 DeprecationWarning: This process (pid=234) is multi-threaded, use of fork() may lead to deadlocks in the child.
[2024-11-14T03:22:13.550+0000] {standard_task_runner.py:72} INFO - Started process 236 to run task
[2024-11-14T03:22:13.579+0000] {logging_mixin.py:190} WARNING - /home/***/.local/lib/python3.12/site-packages/***/settings.py:209 DeprecationWarning: The sql_alchemy_conn option in [core] has been moved to the sql_alchemy_conn option in [database] - the old setting has been used, but please update your config.
[2024-11-14T03:22:13.672+0000] {task_command.py:467} INFO - Running <TaskInstance: model_training_update.train_model scheduled__2024-11-13T00:00:00+00:00 [running]> on host 8cf23de6033a
[2024-11-14T03:22:13.678+0000] {logging_mixin.py:190} WARNING - /home/***/.local/lib/python3.12/site-packages/***/settings.py:470 DeprecationWarning: The sql_alchemy_conn option in [core] has been moved to the sql_alchemy_conn option in [database] - the old setting has been used, but please update your config.
[2024-11-14T03:22:14.041+0000] {taskinstance.py:3131} INFO - Exporting env vars: AIRFLOW_CTX_DAG_OWNER='***' AIRFLOW_CTX_DAG_ID='model_training_update' AIRFLOW_CTX_TASK_ID='train_model' AIRFLOW_CTX_EXECUTION_DATE='2024-11-13T00:00:00+00:00' AIRFLOW_CTX_TRY_NUMBER='1' AIRFLOW_CTX_DAG_RUN_ID='scheduled__2024-11-13T00:00:00+00:00'
[2024-11-14T03:22:14.043+0000] {taskinstance.py:731} INFO - ::endgroup::
[2024-11-14T03:22:14.203+0000] {http.py:173} INFO - Calling HTTP method
[2024-11-14T03:22:14.315+0000] {taskinstance.py:3310} ERROR - Task failed with exception
Traceback (most recent call last):
  File "/home/airflow/.local/lib/python3.12/site-packages/airflow/models/taskinstance.py", line 767, in _execute_task
    result = _execute_callable(context=context, **execute_callable_kwargs)
             ^^^^^^^^^^^^^^^^^^^^^^^^^^^^^^^^^^^^^^^^^^^^^^^^^^^^^^^^^^^^^
  File "/home/airflow/.local/lib/python3.12/site-packages/airflow/models/taskinstance.py", line 733, in _execute_callable
    return ExecutionCallableRunner(
           ^^^^^^^^^^^^^^^^^^^^^^^^
  File "/home/airflow/.local/lib/python3.12/site-packages/airflow/utils/operator_helpers.py", line 252, in run
    return self.func(*args, **kwargs)
           ^^^^^^^^^^^^^^^^^^^^^^^^^^
  File "/home/airflow/.local/lib/python3.12/site-packages/airflow/models/baseoperator.py", line 406, in wrapper
    return func(self, *args, **kwargs)
           ^^^^^^^^^^^^^^^^^^^^^^^^^^^
  File "/home/airflow/.local/lib/python3.12/site-packages/airflow/providers/http/operators/http.py", line 170, in execute
    return self.execute_sync(context=context)
           ^^^^^^^^^^^^^^^^^^^^^^^^^^^^^^^^^^
  File "/home/airflow/.local/lib/python3.12/site-packages/airflow/providers/http/operators/http.py", line 179, in execute_sync
    response = self.hook.run(self.endpoint, self.data, self.headers, self.extra_options)
               ^^^^^^^^^
  File "/home/airflow/.local/lib/python3.12/site-packages/airflow/providers/http/operators/http.py", line 152, in hook
    conn = BaseHook.get_connection(conn_id)
           ^^^^^^^^^^^^^^^^^^^^^^^^^^^^^^^^
  File "/home/airflow/.local/lib/python3.12/site-packages/airflow/hooks/base.py", line 83, in get_connection
    conn = Connection.get_connection_from_secrets(conn_id)
           ^^^^^^^^^^^^^^^^^^^^^^^^^^^^^^^^^^^^^^^^^^^^^^^
  File "/home/airflow/.local/lib/python3.12/site-packages/airflow/models/connection.py", line 537, in get_connection_from_secrets
    raise AirflowNotFoundException(f"The conn_id `{conn_id}` isn't defined")
airflow.exceptions.AirflowNotFoundException: The conn_id `fastapi` isn't defined
[2024-11-14T03:22:14.384+0000] {taskinstance.py:1225} INFO - Marking task as UP_FOR_RETRY. dag_id=model_training_update, task_id=train_model, run_id=scheduled__2024-11-13T00:00:00+00:00, execution_date=20241113T000000, start_date=20241114T032213, end_date=20241114T032214
[2024-11-14T03:22:14.473+0000] {taskinstance.py:340} INFO - ::group::Post task execution logs
[2024-11-14T03:22:14.474+0000] {standard_task_runner.py:124} ERROR - Failed to execute job 2 for task train_model (The conn_id `fastapi` isn't defined; 236)
Traceback (most recent call last):
  File "/home/airflow/.local/lib/python3.12/site-packages/airflow/task/task_runner/standard_task_runner.py", line 117, in _start_by_fork
    ret = args.func(args, dag=self.dag)
          ^^^^^^^^^^^^^^^^^^^^^^^^^^^^^
  File "/home/airflow/.local/lib/python3.12/site-packages/airflow/cli/cli_config.py", line 49, in command
    return func(*args, **kwargs)
           ^^^^^^^^^^^^^^^^^^^^^
  File "/home/airflow/.local/lib/python3.12/site-packages/airflow/utils/cli.py", line 115, in wrapper
    return f(*args, **kwargs)
           ^^^^^^^^^^^^^^^^^^
  File "/home/airflow/.local/lib/python3.12/site-packages/airflow/cli/commands/task_command.py", line 483, in task_run
    task_return_code = _run_task_by_selected_method(args, _dag, ti)
                       ^^^^^^^^^^^^^^^^^^^^^^^^^^^^^^^^^^^^^^^^^^^^
  File "/home/airflow/.local/lib/python3.12/site-packages/airflow/cli/commands/task_command.py", line 256, in _run_task_by_selected_method
    return _run_raw_task(args, ti)
           ^^^^^^^^^^^^^^^^^^^^^^^
  File "/home/airflow/.local/lib/python3.12/site-packages/airflow/cli/commands/task_command.py", line 341, in _run_raw_task
    return ti._run_raw_task(
           ^^^^^^^^^^^^^^^^^
  File "/home/airflow/.local/lib/python3.12/site-packages/airflow/utils/session.py", line 97, in wrapper
    return func(*args, session=session, **kwargs)
           ^^^^^^^^^^^^^^^^^^^^^^^^^^^^^^^^^^^^^^
  File "/home/airflow/.local/lib/python3.12/site-packages/airflow/models/taskinstance.py", line 3004, in _run_raw_task
    return _run_raw_task(
           ^^^^^^^^^^^^^^
  File "/home/airflow/.local/lib/python3.12/site-packages/airflow/models/taskinstance.py", line 273, in _run_raw_task
    TaskInstance._execute_task_with_callbacks(
  File "/home/airflow/.local/lib/python3.12/site-packages/airflow/models/taskinstance.py", line 3158, in _execute_task_with_callbacks
    result = self._execute_task(context, task_orig)
             ^^^^^^^^^^^^^^^^^^^^^^^^^^^^^^^^^^^^^^
  File "/home/airflow/.local/lib/python3.12/site-packages/airflow/models/taskinstance.py", line 3182, in _execute_task
    return _execute_task(self, context, task_orig)
           ^^^^^^^^^^^^^^^^^^^^^^^^^^^^^^^^^^^^^^^
  File "/home/airflow/.local/lib/python3.12/site-packages/airflow/models/taskinstance.py", line 767, in _execute_task
    result = _execute_callable(context=context, **execute_callable_kwargs)
             ^^^^^^^^^^^^^^^^^^^^^^^^^^^^^^^^^^^^^^^^^^^^^^^^^^^^^^^^^^^^^
  File "/home/airflow/.local/lib/python3.12/site-packages/airflow/models/taskinstance.py", line 733, in _execute_callable
    return ExecutionCallableRunner(
           ^^^^^^^^^^^^^^^^^^^^^^^^
  File "/home/airflow/.local/lib/python3.12/site-packages/airflow/utils/operator_helpers.py", line 252, in run
    return self.func(*args, **kwargs)
           ^^^^^^^^^^^^^^^^^^^^^^^^^^
  File "/home/airflow/.local/lib/python3.12/site-packages/airflow/models/baseoperator.py", line 406, in wrapper
    return func(self, *args, **kwargs)
           ^^^^^^^^^^^^^^^^^^^^^^^^^^^
  File "/home/airflow/.local/lib/python3.12/site-packages/airflow/providers/http/operators/http.py", line 170, in execute
    return self.execute_sync(context=context)
           ^^^^^^^^^^^^^^^^^^^^^^^^^^^^^^^^^^
  File "/home/airflow/.local/lib/python3.12/site-packages/airflow/providers/http/operators/http.py", line 179, in execute_sync
    response = self.hook.run(self.endpoint, self.data, self.headers, self.extra_options)
               ^^^^^^^^^
  File "/home/airflow/.local/lib/python3.12/site-packages/airflow/providers/http/operators/http.py", line 152, in hook
    conn = BaseHook.get_connection(conn_id)
           ^^^^^^^^^^^^^^^^^^^^^^^^^^^^^^^^
  File "/home/airflow/.local/lib/python3.12/site-packages/airflow/hooks/base.py", line 83, in get_connection
    conn = Connection.get_connection_from_secrets(conn_id)
           ^^^^^^^^^^^^^^^^^^^^^^^^^^^^^^^^^^^^^^^^^^^^^^^
  File "/home/airflow/.local/lib/python3.12/site-packages/airflow/models/connection.py", line 537, in get_connection_from_secrets
    raise AirflowNotFoundException(f"The conn_id `{conn_id}` isn't defined")
airflow.exceptions.AirflowNotFoundException: The conn_id `fastapi` isn't defined
[2024-11-14T03:22:14.532+0000] {local_task_job_runner.py:266} INFO - Task exited with return code 1
[2024-11-14T03:22:14.586+0000] {taskinstance.py:3900} INFO - 0 downstream tasks scheduled from follow-on schedule check
[2024-11-14T03:22:14.590+0000] {local_task_job_runner.py:245} INFO - ::endgroup::
[2024-11-14T05:09:59.939+0000] {local_task_job_runner.py:123} INFO - ::group::Pre task execution logs
[2024-11-14T05:10:00.175+0000] {taskinstance.py:2612} INFO - Dependencies all met for dep_context=non-requeueable deps ti=<TaskInstance: model_training_update.train_model scheduled__2024-11-13T00:00:00+00:00 [queued]>
[2024-11-14T05:10:00.254+0000] {taskinstance.py:2612} INFO - Dependencies all met for dep_context=requeueable deps ti=<TaskInstance: model_training_update.train_model scheduled__2024-11-13T00:00:00+00:00 [queued]>
[2024-11-14T05:10:00.259+0000] {taskinstance.py:2865} INFO - Starting attempt 1 of 2
[2024-11-14T05:10:00.372+0000] {taskinstance.py:2888} INFO - Executing <Task(HttpOperator): train_model> on 2024-11-13 00:00:00+00:00
[2024-11-14T05:10:00.481+0000] {logging_mixin.py:190} WARNING - /home/***/.local/lib/python3.12/site-packages/***/task/task_runner/standard_task_runner.py:70 DeprecationWarning: This process (pid=239) is multi-threaded, use of fork() may lead to deadlocks in the child.
[2024-11-14T05:10:00.451+0000] {standard_task_runner.py:104} INFO - Running: ['***', 'tasks', 'run', 'model_training_update', 'train_model', 'scheduled__2024-11-13T00:00:00+00:00', '--job-id', '2', '--raw', '--subdir', 'DAGS_FOLDER/DAG.py', '--cfg-path', '/tmp/tmpt9s632hb']
[2024-11-14T05:10:00.492+0000] {standard_task_runner.py:72} INFO - Started process 241 to run task
[2024-11-14T05:10:00.494+0000] {standard_task_runner.py:105} INFO - Job 2: Subtask train_model
[2024-11-14T05:10:00.670+0000] {logging_mixin.py:190} WARNING - /home/***/.local/lib/python3.12/site-packages/***/settings.py:209 DeprecationWarning: The sql_alchemy_conn option in [core] has been moved to the sql_alchemy_conn option in [database] - the old setting has been used, but please update your config.
[2024-11-14T05:10:01.327+0000] {task_command.py:467} INFO - Running <TaskInstance: model_training_update.train_model scheduled__2024-11-13T00:00:00+00:00 [running]> on host a4a9a6d033a8
[2024-11-14T05:10:01.339+0000] {logging_mixin.py:190} WARNING - /home/***/.local/lib/python3.12/site-packages/***/settings.py:470 DeprecationWarning: The sql_alchemy_conn option in [core] has been moved to the sql_alchemy_conn option in [database] - the old setting has been used, but please update your config.
[2024-11-14T05:10:02.068+0000] {taskinstance.py:3131} INFO - Exporting env vars: AIRFLOW_CTX_DAG_OWNER='***' AIRFLOW_CTX_DAG_ID='model_training_update' AIRFLOW_CTX_TASK_ID='train_model' AIRFLOW_CTX_EXECUTION_DATE='2024-11-13T00:00:00+00:00' AIRFLOW_CTX_TRY_NUMBER='1' AIRFLOW_CTX_DAG_RUN_ID='scheduled__2024-11-13T00:00:00+00:00'
[2024-11-14T05:10:02.074+0000] {taskinstance.py:731} INFO - ::endgroup::
[2024-11-14T05:10:02.236+0000] {http.py:173} INFO - Calling HTTP method
[2024-11-14T05:10:02.304+0000] {base.py:84} INFO - Retrieving connection 'fastapi'
[2024-11-14T05:10:02.374+0000] {base.py:84} INFO - Retrieving connection 'fastapi'
[2024-11-14T05:10:09.770+0000] {taskinstance.py:340} INFO - ::group::Post task execution logs
[2024-11-14T05:10:09.771+0000] {taskinstance.py:352} INFO - Marking task as SUCCESS. dag_id=model_training_update, task_id=train_model, run_id=scheduled__2024-11-13T00:00:00+00:00, execution_date=20241113T000000, start_date=20241114T051000, end_date=20241114T051009
[2024-11-14T05:10:09.845+0000] {local_task_job_runner.py:266} INFO - Task exited with return code 0
[2024-11-14T05:10:09.882+0000] {local_task_job_runner.py:245} INFO - ::endgroup::
[2024-11-14T06:27:08.207+0000] {local_task_job_runner.py:123} INFO - ::group::Pre task execution logs
[2024-11-14T06:27:08.376+0000] {taskinstance.py:2612} INFO - Dependencies all met for dep_context=non-requeueable deps ti=<TaskInstance: model_training_update.train_model scheduled__2024-11-13T00:00:00+00:00 [queued]>
[2024-11-14T06:27:08.419+0000] {taskinstance.py:2612} INFO - Dependencies all met for dep_context=requeueable deps ti=<TaskInstance: model_training_update.train_model scheduled__2024-11-13T00:00:00+00:00 [queued]>
[2024-11-14T06:27:08.421+0000] {taskinstance.py:2865} INFO - Starting attempt 1 of 2
[2024-11-14T06:27:08.500+0000] {taskinstance.py:2888} INFO - Executing <Task(HttpOperator): train_model> on 2024-11-13 00:00:00+00:00
[2024-11-14T06:27:08.540+0000] {logging_mixin.py:190} WARNING - /home/***/.local/lib/python3.12/site-packages/***/task/task_runner/standard_task_runner.py:70 DeprecationWarning: This process (pid=281) is multi-threaded, use of fork() may lead to deadlocks in the child.
[2024-11-14T06:27:08.545+0000] {standard_task_runner.py:72} INFO - Started process 282 to run task
[2024-11-14T06:27:08.570+0000] {standard_task_runner.py:104} INFO - Running: ['***', 'tasks', 'run', 'model_training_update', 'train_model', 'scheduled__2024-11-13T00:00:00+00:00', '--job-id', '3', '--raw', '--subdir', 'DAGS_FOLDER/DAG.py', '--cfg-path', '/tmp/tmp8npyz3y1']
[2024-11-14T06:27:08.585+0000] {standard_task_runner.py:105} INFO - Job 3: Subtask train_model
[2024-11-14T06:27:08.748+0000] {logging_mixin.py:190} WARNING - /home/***/.local/lib/python3.12/site-packages/***/settings.py:209 DeprecationWarning: The sql_alchemy_conn option in [core] has been moved to the sql_alchemy_conn option in [database] - the old setting has been used, but please update your config.
[2024-11-14T06:27:09.192+0000] {task_command.py:467} INFO - Running <TaskInstance: model_training_update.train_model scheduled__2024-11-13T00:00:00+00:00 [running]> on host 4038974a3040
[2024-11-14T06:27:09.204+0000] {logging_mixin.py:190} WARNING - /home/***/.local/lib/python3.12/site-packages/***/settings.py:470 DeprecationWarning: The sql_alchemy_conn option in [core] has been moved to the sql_alchemy_conn option in [database] - the old setting has been used, but please update your config.
[2024-11-14T06:27:10.843+0000] {taskinstance.py:3131} INFO - Exporting env vars: AIRFLOW_CTX_DAG_OWNER='***' AIRFLOW_CTX_DAG_ID='model_training_update' AIRFLOW_CTX_TASK_ID='train_model' AIRFLOW_CTX_EXECUTION_DATE='2024-11-13T00:00:00+00:00' AIRFLOW_CTX_TRY_NUMBER='1' AIRFLOW_CTX_DAG_RUN_ID='scheduled__2024-11-13T00:00:00+00:00'
[2024-11-14T06:27:10.862+0000] {taskinstance.py:731} INFO - ::endgroup::
[2024-11-14T06:27:11.150+0000] {http.py:173} INFO - Calling HTTP method
[2024-11-14T06:27:11.374+0000] {base.py:84} INFO - Retrieving connection 'fastapi'
[2024-11-14T06:27:11.598+0000] {base.py:84} INFO - Retrieving connection 'fastapi'
[2024-11-14T06:27:19.602+0000] {taskinstance.py:340} INFO - ::group::Post task execution logs
[2024-11-14T06:27:19.604+0000] {taskinstance.py:352} INFO - Marking task as SUCCESS. dag_id=model_training_update, task_id=train_model, run_id=scheduled__2024-11-13T00:00:00+00:00, execution_date=20241113T000000, start_date=20241114T062708, end_date=20241114T062719
[2024-11-14T06:27:19.676+0000] {local_task_job_runner.py:266} INFO - Task exited with return code 0
[2024-11-14T06:27:19.762+0000] {taskinstance.py:3900} INFO - 0 downstream tasks scheduled from follow-on schedule check
[2024-11-14T06:27:19.767+0000] {local_task_job_runner.py:245} INFO - ::endgroup::
[2024-11-14T07:02:32.993+0000] {local_task_job_runner.py:123} INFO - ::group::Pre task execution logs
[2024-11-14T07:02:33.249+0000] {taskinstance.py:2612} INFO - Dependencies all met for dep_context=non-requeueable deps ti=<TaskInstance: model_training_update.train_model scheduled__2024-11-13T00:00:00+00:00 [queued]>
[2024-11-14T07:02:33.348+0000] {taskinstance.py:2612} INFO - Dependencies all met for dep_context=requeueable deps ti=<TaskInstance: model_training_update.train_model scheduled__2024-11-13T00:00:00+00:00 [queued]>
[2024-11-14T07:02:33.349+0000] {taskinstance.py:2865} INFO - Starting attempt 1 of 2
[2024-11-14T07:02:33.531+0000] {taskinstance.py:2888} INFO - Executing <Task(HttpOperator): train_model> on 2024-11-13 00:00:00+00:00
[2024-11-14T07:02:33.585+0000] {logging_mixin.py:190} WARNING - /home/***/.local/lib/python3.12/site-packages/***/task/task_runner/standard_task_runner.py:70 DeprecationWarning: This process (pid=215) is multi-threaded, use of fork() may lead to deadlocks in the child.
[2024-11-14T07:02:33.607+0000] {standard_task_runner.py:72} INFO - Started process 217 to run task
[2024-11-14T07:02:33.602+0000] {standard_task_runner.py:104} INFO - Running: ['***', 'tasks', 'run', 'model_training_update', 'train_model', 'scheduled__2024-11-13T00:00:00+00:00', '--job-id', '3', '--raw', '--subdir', 'DAGS_FOLDER/DAG.py', '--cfg-path', '/tmp/tmpc56pl9in']
[2024-11-14T07:02:33.647+0000] {standard_task_runner.py:105} INFO - Job 3: Subtask train_model
[2024-11-14T07:02:33.933+0000] {logging_mixin.py:190} WARNING - /home/***/.local/lib/python3.12/site-packages/***/settings.py:209 DeprecationWarning: The sql_alchemy_conn option in [core] has been moved to the sql_alchemy_conn option in [database] - the old setting has been used, but please update your config.
[2024-11-14T07:02:34.495+0000] {task_command.py:467} INFO - Running <TaskInstance: model_training_update.train_model scheduled__2024-11-13T00:00:00+00:00 [running]> on host 61d1a0d6a190
[2024-11-14T07:02:34.504+0000] {logging_mixin.py:190} WARNING - /home/***/.local/lib/python3.12/site-packages/***/settings.py:470 DeprecationWarning: The sql_alchemy_conn option in [core] has been moved to the sql_alchemy_conn option in [database] - the old setting has been used, but please update your config.
[2024-11-14T07:02:36.659+0000] {taskinstance.py:3131} INFO - Exporting env vars: AIRFLOW_CTX_DAG_OWNER='***' AIRFLOW_CTX_DAG_ID='model_training_update' AIRFLOW_CTX_TASK_ID='train_model' AIRFLOW_CTX_EXECUTION_DATE='2024-11-13T00:00:00+00:00' AIRFLOW_CTX_TRY_NUMBER='1' AIRFLOW_CTX_DAG_RUN_ID='scheduled__2024-11-13T00:00:00+00:00'
[2024-11-14T07:02:36.767+0000] {taskinstance.py:731} INFO - ::endgroup::
[2024-11-14T07:02:37.532+0000] {http.py:173} INFO - Calling HTTP method
[2024-11-14T07:02:37.852+0000] {base.py:84} INFO - Retrieving connection 'fastapi'
[2024-11-14T07:02:38.073+0000] {base.py:84} INFO - Retrieving connection 'fastapi'
[2024-11-14T07:02:45.185+0000] {taskinstance.py:340} INFO - ::group::Post task execution logs
[2024-11-14T07:02:45.189+0000] {taskinstance.py:352} INFO - Marking task as SUCCESS. dag_id=model_training_update, task_id=train_model, run_id=scheduled__2024-11-13T00:00:00+00:00, execution_date=20241113T000000, start_date=20241114T070233, end_date=20241114T070245
[2024-11-14T07:02:45.271+0000] {local_task_job_runner.py:266} INFO - Task exited with return code 0
[2024-11-14T07:02:45.367+0000] {taskinstance.py:3900} INFO - 0 downstream tasks scheduled from follow-on schedule check
[2024-11-14T07:02:45.372+0000] {local_task_job_runner.py:245} INFO - ::endgroup::
