[2024-11-14T04:17:24.392+0000] {local_task_job_runner.py:123} INFO - ::group::Pre task execution logs
[2024-11-14T04:17:24.466+0000] {taskinstance.py:2612} INFO - Dependencies all met for dep_context=non-requeueable deps ti=<TaskInstance: model_training_update.update_data manual__2024-11-14T04:17:19.317299+00:00 [queued]>
[2024-11-14T04:17:24.501+0000] {taskinstance.py:2612} INFO - Dependencies all met for dep_context=requeueable deps ti=<TaskInstance: model_training_update.update_data manual__2024-11-14T04:17:19.317299+00:00 [queued]>
[2024-11-14T04:17:24.503+0000] {taskinstance.py:2865} INFO - Starting attempt 1 of 2
[2024-11-14T04:17:24.573+0000] {taskinstance.py:2888} INFO - Executing <Task(HttpOperator): update_data> on 2024-11-14 04:17:19.317299+00:00
[2024-11-14T04:17:24.619+0000] {logging_mixin.py:190} WARNING - /home/***/.local/lib/python3.12/site-packages/***/task/task_runner/standard_task_runner.py:70 DeprecationWarning: This process (pid=798) is multi-threaded, use of fork() may lead to deadlocks in the child.
[2024-11-14T04:17:24.627+0000] {standard_task_runner.py:72} INFO - Started process 800 to run task
[2024-11-14T04:17:24.622+0000] {standard_task_runner.py:104} INFO - Running: ['***', 'tasks', 'run', 'model_training_update', 'update_data', 'manual__2024-11-14T04:17:19.317299+00:00', '--job-id', '11', '--raw', '--subdir', 'DAGS_FOLDER/DAG.py', '--cfg-path', '/tmp/tmpktvu38i3']
[2024-11-14T04:17:24.632+0000] {standard_task_runner.py:105} INFO - Job 11: Subtask update_data
[2024-11-14T04:17:24.839+0000] {logging_mixin.py:190} WARNING - /home/***/.local/lib/python3.12/site-packages/***/settings.py:209 DeprecationWarning: The sql_alchemy_conn option in [core] has been moved to the sql_alchemy_conn option in [database] - the old setting has been used, but please update your config.
[2024-11-14T04:17:25.234+0000] {task_command.py:467} INFO - Running <TaskInstance: model_training_update.update_data manual__2024-11-14T04:17:19.317299+00:00 [running]> on host 8cf23de6033a
[2024-11-14T04:17:25.771+0000] {taskinstance.py:3131} INFO - Exporting env vars: AIRFLOW_CTX_DAG_OWNER='***' AIRFLOW_CTX_DAG_ID='model_training_update' AIRFLOW_CTX_TASK_ID='update_data' AIRFLOW_CTX_EXECUTION_DATE='2024-11-14T04:17:19.317299+00:00' AIRFLOW_CTX_TRY_NUMBER='1' AIRFLOW_CTX_DAG_RUN_ID='manual__2024-11-14T04:17:19.317299+00:00'
[2024-11-14T04:17:25.778+0000] {taskinstance.py:731} INFO - ::endgroup::
[2024-11-14T04:17:25.857+0000] {http.py:173} INFO - Calling HTTP method
[2024-11-14T04:17:25.900+0000] {base.py:84} INFO - Retrieving connection 'fastapi'
[2024-11-14T04:17:25.941+0000] {base.py:84} INFO - Retrieving connection 'fastapi'
[2024-11-14T04:17:26.013+0000] {http.py:204} ERROR - HTTP error: Unprocessable Entity
[2024-11-14T04:17:26.015+0000] {http.py:205} ERROR - {"detail":[{"type":"missing","loc":["body","file"],"msg":"Field required","input":null}]}
[2024-11-14T04:17:26.069+0000] {taskinstance.py:3310} ERROR - Task failed with exception
Traceback (most recent call last):
  File "/home/airflow/.local/lib/python3.12/site-packages/airflow/providers/http/hooks/http.py", line 202, in check_response
    response.raise_for_status()
  File "/home/airflow/.local/lib/python3.12/site-packages/requests/models.py", line 1024, in raise_for_status
    raise HTTPError(http_error_msg, response=self)
requests.exceptions.HTTPError: 422 Client Error: Unprocessable Entity for url: http://fastapi:8000/update_data

During handling of the above exception, another exception occurred:

Traceback (most recent call last):
  File "/home/airflow/.local/lib/python3.12/site-packages/airflow/models/taskinstance.py", line 767, in _execute_task
    result = _execute_callable(context=context, **execute_callable_kwargs)
             ^^^^^^^^^^^^^^^^^^^^^^^^^^^^^^^^^^^^^^^^^^^^^^^^^^^^^^^^^^^^^
  File "/home/airflow/.local/lib/python3.12/site-packages/airflow/models/taskinstance.py", line 733, in _execute_callable
    return ExecutionCallableRunner(
           ^^^^^^^^^^^^^^^^^^^^^^^^
  File "/home/airflow/.local/lib/python3.12/site-packages/airflow/utils/operator_helpers.py", line 252, in run
    return self.func(*args, **kwargs)
           ^^^^^^^^^^^^^^^^^^^^^^^^^^
  File "/home/airflow/.local/lib/python3.12/site-packages/airflow/models/baseoperator.py", line 406, in wrapper
    return func(self, *args, **kwargs)
           ^^^^^^^^^^^^^^^^^^^^^^^^^^^
  File "/home/airflow/.local/lib/python3.12/site-packages/airflow/providers/http/operators/http.py", line 170, in execute
    return self.execute_sync(context=context)
           ^^^^^^^^^^^^^^^^^^^^^^^^^^^^^^^^^^
  File "/home/airflow/.local/lib/python3.12/site-packages/airflow/providers/http/operators/http.py", line 179, in execute_sync
    response = self.hook.run(self.endpoint, self.data, self.headers, self.extra_options)
               ^^^^^^^^^^^^^^^^^^^^^^^^^^^^^^^^^^^^^^^^^^^^^^^^^^^^^^^^^^^^^^^^^^^^^^^^^
  File "/home/airflow/.local/lib/python3.12/site-packages/airflow/providers/http/hooks/http.py", line 191, in run
    return self.run_and_check(session, prepped_request, extra_options)
           ^^^^^^^^^^^^^^^^^^^^^^^^^^^^^^^^^^^^^^^^^^^^^^^^^^^^^^^^^^^
  File "/home/airflow/.local/lib/python3.12/site-packages/airflow/providers/http/hooks/http.py", line 244, in run_and_check
    self.check_response(response)
  File "/home/airflow/.local/lib/python3.12/site-packages/airflow/providers/http/hooks/http.py", line 206, in check_response
    raise AirflowException(str(response.status_code) + ":" + response.reason)
airflow.exceptions.AirflowException: 422:Unprocessable Entity
[2024-11-14T04:17:26.141+0000] {taskinstance.py:1225} INFO - Marking task as UP_FOR_RETRY. dag_id=model_training_update, task_id=update_data, run_id=manual__2024-11-14T04:17:19.317299+00:00, execution_date=20241114T041719, start_date=20241114T041724, end_date=20241114T041726
[2024-11-14T04:17:26.209+0000] {taskinstance.py:340} INFO - ::group::Post task execution logs
[2024-11-14T04:17:26.212+0000] {standard_task_runner.py:124} ERROR - Failed to execute job 11 for task update_data (422:Unprocessable Entity; 800)
Traceback (most recent call last):
  File "/home/airflow/.local/lib/python3.12/site-packages/airflow/providers/http/hooks/http.py", line 202, in check_response
    response.raise_for_status()
  File "/home/airflow/.local/lib/python3.12/site-packages/requests/models.py", line 1024, in raise_for_status
    raise HTTPError(http_error_msg, response=self)
requests.exceptions.HTTPError: 422 Client Error: Unprocessable Entity for url: http://fastapi:8000/update_data

During handling of the above exception, another exception occurred:

Traceback (most recent call last):
  File "/home/airflow/.local/lib/python3.12/site-packages/airflow/task/task_runner/standard_task_runner.py", line 117, in _start_by_fork
    ret = args.func(args, dag=self.dag)
          ^^^^^^^^^^^^^^^^^^^^^^^^^^^^^
  File "/home/airflow/.local/lib/python3.12/site-packages/airflow/cli/cli_config.py", line 49, in command
    return func(*args, **kwargs)
           ^^^^^^^^^^^^^^^^^^^^^
  File "/home/airflow/.local/lib/python3.12/site-packages/airflow/utils/cli.py", line 115, in wrapper
    return f(*args, **kwargs)
           ^^^^^^^^^^^^^^^^^^
  File "/home/airflow/.local/lib/python3.12/site-packages/airflow/cli/commands/task_command.py", line 483, in task_run
    task_return_code = _run_task_by_selected_method(args, _dag, ti)
                       ^^^^^^^^^^^^^^^^^^^^^^^^^^^^^^^^^^^^^^^^^^^^
  File "/home/airflow/.local/lib/python3.12/site-packages/airflow/cli/commands/task_command.py", line 256, in _run_task_by_selected_method
    return _run_raw_task(args, ti)
           ^^^^^^^^^^^^^^^^^^^^^^^
  File "/home/airflow/.local/lib/python3.12/site-packages/airflow/cli/commands/task_command.py", line 341, in _run_raw_task
    return ti._run_raw_task(
           ^^^^^^^^^^^^^^^^^
  File "/home/airflow/.local/lib/python3.12/site-packages/airflow/utils/session.py", line 97, in wrapper
    return func(*args, session=session, **kwargs)
           ^^^^^^^^^^^^^^^^^^^^^^^^^^^^^^^^^^^^^^
  File "/home/airflow/.local/lib/python3.12/site-packages/airflow/models/taskinstance.py", line 3004, in _run_raw_task
    return _run_raw_task(
           ^^^^^^^^^^^^^^
  File "/home/airflow/.local/lib/python3.12/site-packages/airflow/models/taskinstance.py", line 273, in _run_raw_task
    TaskInstance._execute_task_with_callbacks(
  File "/home/airflow/.local/lib/python3.12/site-packages/airflow/models/taskinstance.py", line 3158, in _execute_task_with_callbacks
    result = self._execute_task(context, task_orig)
             ^^^^^^^^^^^^^^^^^^^^^^^^^^^^^^^^^^^^^^
  File "/home/airflow/.local/lib/python3.12/site-packages/airflow/models/taskinstance.py", line 3182, in _execute_task
    return _execute_task(self, context, task_orig)
           ^^^^^^^^^^^^^^^^^^^^^^^^^^^^^^^^^^^^^^^
  File "/home/airflow/.local/lib/python3.12/site-packages/airflow/models/taskinstance.py", line 767, in _execute_task
    result = _execute_callable(context=context, **execute_callable_kwargs)
             ^^^^^^^^^^^^^^^^^^^^^^^^^^^^^^^^^^^^^^^^^^^^^^^^^^^^^^^^^^^^^
  File "/home/airflow/.local/lib/python3.12/site-packages/airflow/models/taskinstance.py", line 733, in _execute_callable
    return ExecutionCallableRunner(
           ^^^^^^^^^^^^^^^^^^^^^^^^
  File "/home/airflow/.local/lib/python3.12/site-packages/airflow/utils/operator_helpers.py", line 252, in run
    return self.func(*args, **kwargs)
           ^^^^^^^^^^^^^^^^^^^^^^^^^^
  File "/home/airflow/.local/lib/python3.12/site-packages/airflow/models/baseoperator.py", line 406, in wrapper
    return func(self, *args, **kwargs)
           ^^^^^^^^^^^^^^^^^^^^^^^^^^^
  File "/home/airflow/.local/lib/python3.12/site-packages/airflow/providers/http/operators/http.py", line 170, in execute
    return self.execute_sync(context=context)
           ^^^^^^^^^^^^^^^^^^^^^^^^^^^^^^^^^^
  File "/home/airflow/.local/lib/python3.12/site-packages/airflow/providers/http/operators/http.py", line 179, in execute_sync
    response = self.hook.run(self.endpoint, self.data, self.headers, self.extra_options)
               ^^^^^^^^^^^^^^^^^^^^^^^^^^^^^^^^^^^^^^^^^^^^^^^^^^^^^^^^^^^^^^^^^^^^^^^^^
  File "/home/airflow/.local/lib/python3.12/site-packages/airflow/providers/http/hooks/http.py", line 191, in run
    return self.run_and_check(session, prepped_request, extra_options)
           ^^^^^^^^^^^^^^^^^^^^^^^^^^^^^^^^^^^^^^^^^^^^^^^^^^^^^^^^^^^
  File "/home/airflow/.local/lib/python3.12/site-packages/airflow/providers/http/hooks/http.py", line 244, in run_and_check
    self.check_response(response)
  File "/home/airflow/.local/lib/python3.12/site-packages/airflow/providers/http/hooks/http.py", line 206, in check_response
    raise AirflowException(str(response.status_code) + ":" + response.reason)
airflow.exceptions.AirflowException: 422:Unprocessable Entity
[2024-11-14T04:17:26.288+0000] {local_task_job_runner.py:266} INFO - Task exited with return code 1
[2024-11-14T04:17:26.398+0000] {taskinstance.py:3900} INFO - 0 downstream tasks scheduled from follow-on schedule check
[2024-11-14T04:17:26.404+0000] {local_task_job_runner.py:245} INFO - ::endgroup::
