[2024-11-05T02:04:00.654+0000] {local_task_job_runner.py:123} INFO - ::group::Pre task execution logs
[2024-11-05T02:04:00.781+0000] {taskinstance.py:2612} INFO - Dependencies all met for dep_context=non-requeueable deps ti=<TaskInstance: model_training_update.update_data manual__2024-11-05T02:03:55.635094+00:00 [queued]>
[2024-11-05T02:04:00.814+0000] {taskinstance.py:2612} INFO - Dependencies all met for dep_context=requeueable deps ti=<TaskInstance: model_training_update.update_data manual__2024-11-05T02:03:55.635094+00:00 [queued]>
[2024-11-05T02:04:00.816+0000] {taskinstance.py:2865} INFO - Starting attempt 1 of 2
[2024-11-05T02:04:00.899+0000] {taskinstance.py:2888} INFO - Executing <Task(HttpOperator): update_data> on 2024-11-05 02:03:55.635094+00:00
[2024-11-05T02:04:00.940+0000] {standard_task_runner.py:104} INFO - Running: ['***', 'tasks', 'run', 'model_training_update', 'update_data', 'manual__2024-11-05T02:03:55.635094+00:00', '--job-id', '17', '--raw', '--subdir', 'DAGS_FOLDER/DAG.py', '--cfg-path', '/tmp/tmppxjl4izs']
[2024-11-05T02:04:00.953+0000] {logging_mixin.py:190} WARNING - /home/***/.local/lib/python3.12/site-packages/***/task/task_runner/standard_task_runner.py:70 DeprecationWarning: This process (pid=401) is multi-threaded, use of fork() may lead to deadlocks in the child.
[2024-11-05T02:04:00.956+0000] {standard_task_runner.py:105} INFO - Job 17: Subtask update_data
[2024-11-05T02:04:00.956+0000] {standard_task_runner.py:72} INFO - Started process 403 to run task
[2024-11-05T02:04:01.155+0000] {logging_mixin.py:190} WARNING - /home/***/.local/lib/python3.12/site-packages/***/settings.py:209 DeprecationWarning: The sql_alchemy_conn option in [core] has been moved to the sql_alchemy_conn option in [database] - the old setting has been used, but please update your config.
[2024-11-05T02:04:01.608+0000] {task_command.py:467} INFO - Running <TaskInstance: model_training_update.update_data manual__2024-11-05T02:03:55.635094+00:00 [running]> on host 99e6a43400bc
[2024-11-05T02:04:02.268+0000] {taskinstance.py:3131} INFO - Exporting env vars: AIRFLOW_CTX_DAG_OWNER='***' AIRFLOW_CTX_DAG_ID='model_training_update' AIRFLOW_CTX_TASK_ID='update_data' AIRFLOW_CTX_EXECUTION_DATE='2024-11-05T02:03:55.635094+00:00' AIRFLOW_CTX_TRY_NUMBER='1' AIRFLOW_CTX_DAG_RUN_ID='manual__2024-11-05T02:03:55.635094+00:00'
[2024-11-05T02:04:02.271+0000] {taskinstance.py:731} INFO - ::endgroup::
[2024-11-05T02:04:02.394+0000] {http.py:173} INFO - Calling HTTP method
[2024-11-05T02:04:02.474+0000] {base.py:84} INFO - Retrieving connection 'http://localhost:80/docs'
[2024-11-05T02:04:02.585+0000] {base.py:84} INFO - Retrieving connection 'http://localhost:80/docs'
[2024-11-05T02:04:02.590+0000] {taskinstance.py:3310} ERROR - Task failed with exception
Traceback (most recent call last):
  File "/home/airflow/.local/lib/python3.12/site-packages/airflow/models/taskinstance.py", line 767, in _execute_task
    result = _execute_callable(context=context, **execute_callable_kwargs)
             ^^^^^^^^^^^^^^^^^^^^^^^^^^^^^^^^^^^^^^^^^^^^^^^^^^^^^^^^^^^^^
  File "/home/airflow/.local/lib/python3.12/site-packages/airflow/models/taskinstance.py", line 733, in _execute_callable
    return ExecutionCallableRunner(
           ^^^^^^^^^^^^^^^^^^^^^^^^
  File "/home/airflow/.local/lib/python3.12/site-packages/airflow/utils/operator_helpers.py", line 252, in run
    return self.func(*args, **kwargs)
           ^^^^^^^^^^^^^^^^^^^^^^^^^^
  File "/home/airflow/.local/lib/python3.12/site-packages/airflow/models/baseoperator.py", line 406, in wrapper
    return func(self, *args, **kwargs)
           ^^^^^^^^^^^^^^^^^^^^^^^^^^^
  File "/home/airflow/.local/lib/python3.12/site-packages/airflow/providers/http/operators/http.py", line 170, in execute
    return self.execute_sync(context=context)
           ^^^^^^^^^^^^^^^^^^^^^^^^^^^^^^^^^^
  File "/home/airflow/.local/lib/python3.12/site-packages/airflow/providers/http/operators/http.py", line 179, in execute_sync
    response = self.hook.run(self.endpoint, self.data, self.headers, self.extra_options)
               ^^^^^^^^^^^^^^^^^^^^^^^^^^^^^^^^^^^^^^^^^^^^^^^^^^^^^^^^^^^^^^^^^^^^^^^^^
  File "/home/airflow/.local/lib/python3.12/site-packages/airflow/providers/http/hooks/http.py", line 189, in run
    prepped_request = session.prepare_request(req)
                      ^^^^^^^^^^^^^^^^^^^^^^^^^^^^
  File "/home/airflow/.local/lib/python3.12/site-packages/requests/sessions.py", line 484, in prepare_request
    p.prepare(
  File "/home/airflow/.local/lib/python3.12/site-packages/requests/models.py", line 367, in prepare
    self.prepare_url(url, params)
  File "/home/airflow/.local/lib/python3.12/site-packages/requests/models.py", line 444, in prepare_url
    raise InvalidURL(f"Invalid URL {url!r}: No host supplied")
requests.exceptions.InvalidURL: Invalid URL 'http:///update_data': No host supplied
[2024-11-05T02:04:02.681+0000] {taskinstance.py:1225} INFO - Marking task as UP_FOR_RETRY. dag_id=model_training_update, task_id=update_data, run_id=manual__2024-11-05T02:03:55.635094+00:00, execution_date=20241105T020355, start_date=20241105T020400, end_date=20241105T020402
[2024-11-05T02:04:02.774+0000] {taskinstance.py:340} INFO - ::group::Post task execution logs
[2024-11-05T02:04:02.775+0000] {standard_task_runner.py:124} ERROR - Failed to execute job 17 for task update_data (Invalid URL 'http:///update_data': No host supplied; 403)
Traceback (most recent call last):
  File "/home/airflow/.local/lib/python3.12/site-packages/airflow/task/task_runner/standard_task_runner.py", line 117, in _start_by_fork
    ret = args.func(args, dag=self.dag)
          ^^^^^^^^^^^^^^^^^^^^^^^^^^^^^
  File "/home/airflow/.local/lib/python3.12/site-packages/airflow/cli/cli_config.py", line 49, in command
    return func(*args, **kwargs)
           ^^^^^^^^^^^^^^^^^^^^^
  File "/home/airflow/.local/lib/python3.12/site-packages/airflow/utils/cli.py", line 115, in wrapper
    return f(*args, **kwargs)
           ^^^^^^^^^^^^^^^^^^
  File "/home/airflow/.local/lib/python3.12/site-packages/airflow/cli/commands/task_command.py", line 483, in task_run
    task_return_code = _run_task_by_selected_method(args, _dag, ti)
                       ^^^^^^^^^^^^^^^^^^^^^^^^^^^^^^^^^^^^^^^^^^^^
  File "/home/airflow/.local/lib/python3.12/site-packages/airflow/cli/commands/task_command.py", line 256, in _run_task_by_selected_method
    return _run_raw_task(args, ti)
           ^^^^^^^^^^^^^^^^^^^^^^^
  File "/home/airflow/.local/lib/python3.12/site-packages/airflow/cli/commands/task_command.py", line 341, in _run_raw_task
    return ti._run_raw_task(
           ^^^^^^^^^^^^^^^^^
  File "/home/airflow/.local/lib/python3.12/site-packages/airflow/utils/session.py", line 97, in wrapper
    return func(*args, session=session, **kwargs)
           ^^^^^^^^^^^^^^^^^^^^^^^^^^^^^^^^^^^^^^
  File "/home/airflow/.local/lib/python3.12/site-packages/airflow/models/taskinstance.py", line 3004, in _run_raw_task
    return _run_raw_task(
           ^^^^^^^^^^^^^^
  File "/home/airflow/.local/lib/python3.12/site-packages/airflow/models/taskinstance.py", line 273, in _run_raw_task
    TaskInstance._execute_task_with_callbacks(
  File "/home/airflow/.local/lib/python3.12/site-packages/airflow/models/taskinstance.py", line 3158, in _execute_task_with_callbacks
    result = self._execute_task(context, task_orig)
             ^^^^^^^^^^^^^^^^^^^^^^^^^^^^^^^^^^^^^^
  File "/home/airflow/.local/lib/python3.12/site-packages/airflow/models/taskinstance.py", line 3182, in _execute_task
    return _execute_task(self, context, task_orig)
           ^^^^^^^^^^^^^^^^^^^^^^^^^^^^^^^^^^^^^^^
  File "/home/airflow/.local/lib/python3.12/site-packages/airflow/models/taskinstance.py", line 767, in _execute_task
    result = _execute_callable(context=context, **execute_callable_kwargs)
             ^^^^^^^^^^^^^^^^^^^^^^^^^^^^^^^^^^^^^^^^^^^^^^^^^^^^^^^^^^^^^
  File "/home/airflow/.local/lib/python3.12/site-packages/airflow/models/taskinstance.py", line 733, in _execute_callable
    return ExecutionCallableRunner(
           ^^^^^^^^^^^^^^^^^^^^^^^^
  File "/home/airflow/.local/lib/python3.12/site-packages/airflow/utils/operator_helpers.py", line 252, in run
    return self.func(*args, **kwargs)
           ^^^^^^^^^^^^^^^^^^^^^^^^^^
  File "/home/airflow/.local/lib/python3.12/site-packages/airflow/models/baseoperator.py", line 406, in wrapper
    return func(self, *args, **kwargs)
           ^^^^^^^^^^^^^^^^^^^^^^^^^^^
  File "/home/airflow/.local/lib/python3.12/site-packages/airflow/providers/http/operators/http.py", line 170, in execute
    return self.execute_sync(context=context)
           ^^^^^^^^^^^^^^^^^^^^^^^^^^^^^^^^^^
  File "/home/airflow/.local/lib/python3.12/site-packages/airflow/providers/http/operators/http.py", line 179, in execute_sync
    response = self.hook.run(self.endpoint, self.data, self.headers, self.extra_options)
               ^^^^^^^^^^^^^^^^^^^^^^^^^^^^^^^^^^^^^^^^^^^^^^^^^^^^^^^^^^^^^^^^^^^^^^^^^
  File "/home/airflow/.local/lib/python3.12/site-packages/airflow/providers/http/hooks/http.py", line 189, in run
    prepped_request = session.prepare_request(req)
                      ^^^^^^^^^^^^^^^^^^^^^^^^^^^^
  File "/home/airflow/.local/lib/python3.12/site-packages/requests/sessions.py", line 484, in prepare_request
    p.prepare(
  File "/home/airflow/.local/lib/python3.12/site-packages/requests/models.py", line 367, in prepare
    self.prepare_url(url, params)
  File "/home/airflow/.local/lib/python3.12/site-packages/requests/models.py", line 444, in prepare_url
    raise InvalidURL(f"Invalid URL {url!r}: No host supplied")
requests.exceptions.InvalidURL: Invalid URL 'http:///update_data': No host supplied
[2024-11-05T02:04:02.811+0000] {local_task_job_runner.py:266} INFO - Task exited with return code 1
[2024-11-05T02:04:02.880+0000] {local_task_job_runner.py:245} INFO - ::endgroup::
